<?xml version='1.0' encoding='utf-8'?>
<robot name="go2">
  <link name="body">
    <inertial>
      <origin rpy="0 0 0" xyz="0.021112 0 -0.005366" />
      <mass value="6.921" />
      <inertia ixx="0.02448" ixy="0.00012166" ixz="0.0014849" iyy="0.098077" iyz="-3.12E-05" izz="0.107" />
    </inertial>
    <visual>
      <origin rpy="0 0 0" xyz="0 0 0" />
      <geometry>
        <mesh filename="/home/rml/ros2_ws/install/go2_description/share/go2_description/models/go2/dae/body.dae" />
      </geometry>
      <material name="">
        <color rgba="1 1 1 1" />
      </material>
    </visual>
    <collision>
      <origin rpy="0 0 0" xyz="0 0 0" />
      <geometry>
        <box size="0.3762 0.0935 0.114" />
      </geometry>
    </collision>
  </link>
  <link name="Head_upper">
    <inertial>
      <origin rpy="0 0 0" xyz="0 0 0" />
      <mass value="0.001" />
      <inertia ixx="9.6e-06" ixy="0" ixz="0" iyy="9.6e-06" iyz="0" izz="9.6e-06" />
    </inertial>
    <collision>
      <origin rpy="0 0 0" xyz="0 0 0" />
      <geometry>
        <cylinder length="0.09" radius="0.05" />
      </geometry>
    </collision>
  </link>
  <joint name="Head_upper_joint" type="fixed">
    <origin rpy="0 0 0" xyz="0.285 0 0.01" />
    <parent link="body" />
    <child link="Head_upper" />
    <axis xyz="0 0 0" />
  </joint>
  <link name="Head_lower">
    <inertial>
      <origin rpy="0 0 0" xyz="0 0 0" />
      <mass value="0.001" />
      <inertia ixx="9.6e-06" ixy="0" ixz="0" iyy="9.6e-06" iyz="0" izz="9.6e-06" />
    </inertial>
    <collision>
      <origin rpy="0 0 0" xyz="0 0 0" />
      <geometry>
        <sphere radius="0.047" />
      </geometry>
    </collision>
  </link>
  <joint name="Head_lower_joint" type="fixed">
    <origin rpy="0 0 0" xyz="0.008 0 -0.07" />
    <parent link="Head_upper" />
    <child link="Head_lower" />
    <axis xyz="0 0 0" />
  </joint>
  <link name="hip0">
    <inertial>
      <origin rpy="0 0 0" xyz="-0.0054 0.00194 -0.000105" />
      <mass value="0.678" />
      <inertia ixx="0.00048" ixy="-3.01E-06" ixz="1.11E-06" iyy="0.000884" iyz="-1.42E-06" izz="0.000596" />
    </inertial>
    <visual>
      <origin rpy="0 0 0" xyz="0 0 0" />
      <geometry>
        <mesh filename="/home/rml/ros2_ws/install/go2_description/share/go2_description/models/go2/dae/hip.dae" />
      </geometry>
      <material name="">
        <color rgba="1 1 1 1" />
      </material>
    </visual>
    <collision>
      <origin rpy="1.5707963267948966 0 0" xyz="0 0.08 0" />
      <geometry>
        <cylinder length="0.04" radius="0.046" />
      </geometry>
    </collision>
  </link>
  <joint name="j_abad_0" type="revolute">
    <origin rpy="0 0 0" xyz="0.1934 0.0465 0" />
    <parent link="body" />
    <child link="hip0" />
    <axis xyz="1 0 0" />
    <limit effort="23.7" lower="-1.0472" upper="1.0472" velocity="30.1" />
  </joint>
  <link name="hip0_rotor">
    <inertial>
      <origin rpy="0 0 0" xyz="0.0 0.0 0.0" />
      <mass value="0.089" />
      <inertia ixx="0.000111842" ixy="0.0" ixz="0.0" iyy="0.000059647" iyz="0.0" izz="0.000059647" />
    </inertial>
  </link>
  <joint name="hip0_rotor_joint" type="fixed">
    <origin rpy="0 0 0" xyz="0.11215 0.04675 0" />
    <parent link="body" />
    <child link="hip0_rotor" />
  </joint>
  <link name="upper0">
    <inertial>
      <origin rpy="0 0 0" xyz="-0.00374 -0.0223 -0.0327" />
      <mass value="1.152" />
      <inertia ixx="0.00584" ixy="8.72E-05" ixz="-0.000289" iyy="0.0058" iyz="0.000808" izz="0.00103" />
    </inertial>
    <visual>
      <origin rpy="0 0 0" xyz="0 0 0" />
      <geometry>
        <mesh filename="/home/rml/ros2_ws/install/go2_description/share/go2_description/models/go2/dae/thigh.dae" />
      </geometry>
      <material name="">
        <color rgba="1 1 1 1" />
      </material>
    </visual>
    <collision>
      <origin rpy="0 1.5707963267948966 0" xyz="0 0 -0.1065" />
      <geometry>
        <box size="0.213 0.0245 0.034" />
      </geometry>
    </collision>
  </link>
  <joint name="j_hip_0" type="revolute">
    <origin rpy="0 0 0" xyz="0 0.0955 0" />
    <parent link="hip0" />
    <child link="upper0" />
    <axis xyz="0 1 0" />
    <limit effort="23.7" lower="-1.5708" upper="3.4907" velocity="30.1" />
  </joint>
  <link name="upper0_rotor">
    <inertial>
      <origin rpy="0 0 0" xyz="0.0 0.0 0.0" />
      <mass value="0.089" />
      <inertia ixx="0.000059647" ixy="0.0" ixz="0.0" iyy="0.000111842" iyz="0.0" izz="0.000059647" />
    </inertial>
  </link>
  <joint name="upper0_rotor_joint" type="fixed">
    <origin rpy="0 0 0" xyz="0 -0.00015 0" />
    <parent link="hip0" />
    <child link="upper0_rotor" />
  </joint>
  <link name="lower0">
    <inertial>
      <origin rpy="0 0 0" xyz="0.00548 -0.000975 -0.115" />
      <mass value="0.154" />
      <inertia ixx="0.00108" ixy="3.4E-07" ixz="1.72E-05" iyy="0.0011" iyz="8.28E-06" izz="3.29E-05" />
    </inertial>
    <visual>
      <origin rpy="0 0 0" xyz="0 0 0" />
      <geometry>
        <mesh filename="/home/rml/ros2_ws/install/go2_description/share/go2_description/models/go2/dae/calf.dae" />
      </geometry>
      <material name="">
        <color rgba="1 1 1 1" />
      </material>
    </visual>
    <collision>
      <origin rpy="0 -0.21 0" xyz="0.008 0 -0.06" />
      <geometry>
        <cylinder length="0.12" radius="0.012" />
      </geometry>
    </collision>
  </link>
  <joint name="j_knee_0" type="revolute">
    <origin rpy="0 0 0" xyz="0 0 -0.213" />
    <parent link="upper0" />
    <child link="lower0" />
    <axis xyz="0 1 0" />
    <limit effort="45.43" lower="-2.7227" upper="-0.83776" velocity="15.70" />
  </joint>
  <link name="lower0_lower">
    <collision>
      <origin rpy="0 0 0" xyz="0 0 0" />
      <geometry>
        <cylinder length="0.065" radius="0.011" />
      </geometry>
    </collision>
  <inertial><origin rpy="0 0 0" xyz="0 0 0" /><mass value="0.001" /><inertia ixx="1e-06" ixy="0" ixz="0" iyy="1e-06" iyz="0" izz="1e-06" /></inertial></link>
  <joint name="lower0_lower_joint" type="fixed">
    <origin rpy="0 0.05 0" xyz="0.020 0 -0.148" />
    <parent link="lower0" />
    <child link="lower0_lower" />
    <axis xyz="0 0 0" />
  </joint>
  <link name="lower0_lower1">
    <collision>
      <origin rpy="0 0 0" xyz="0 0 0" />
      <geometry>
        <cylinder length="0.03" radius="0.0155" />
      </geometry>
    </collision>
  <inertial><origin rpy="0 0 0" xyz="0 0 0" /><mass value="0.001" /><inertia ixx="1e-06" ixy="0" ixz="0" iyy="1e-06" iyz="0" izz="1e-06" /></inertial></link>
  <joint name="lower0_lower1_joint" type="fixed">
    <origin rpy="0 0.48 0" xyz="-0.01 0 -0.04" />
    <parent link="lower0_lower" />
    <child link="lower0_lower1" />
    <axis xyz="0 0 0" />
  </joint>
  <link name="lower0_rotor">
    <inertial>
      <origin rpy="0 0 0" xyz="0.0 0.0 0.0" />
      <mass value="0.089" />
      <inertia ixx="0.000059647" ixy="0.0" ixz="0.0" iyy="0.000111842" iyz="0.0" izz="0.000059647" />
    </inertial>
  </link>
  <joint name="lower0_rotor_joint" type="fixed">
    <origin rpy="0 0 0" xyz="0 -0.03235 0" />
    <parent link="upper0" />
    <child link="lower0_rotor" />
  </joint>
  <link name="toe0">
    <inertial>
      <origin rpy="0 0 0" xyz="0 0 0" />
      <mass value="0.04" />
      <inertia ixx="9.6e-06" ixy="0" ixz="0" iyy="9.6e-06" iyz="0" izz="9.6e-06" />
    </inertial>
    <visual>
      <origin rpy="0 0 0" xyz="0 0 0" />
      <geometry>
        <mesh filename="/home/rml/ros2_ws/install/go2_description/share/go2_description/models/go2/dae/foot.dae" />
      </geometry>
      <material name="">
        <color rgba="1 1 1 1" />
      </material>
    </visual>
    <collision>
      <origin rpy="0 0 0" xyz="-0.002 0 0" />
      <geometry>
        <sphere radius="0.022" />
      </geometry>
    </collision>
  </link>
  <joint name="jtoe0" type="fixed">
    <origin rpy="0 0 0" xyz="0 0 -0.213" />
    <parent link="lower0" />
    <child link="toe0" />
    <axis xyz="0 0 0" />
  </joint>
  <link name="hip2">
    <inertial>
      <origin rpy="0 0 0" xyz="-0.0054 -0.00194 -0.000105" />
      <mass value="0.678" />
      <inertia ixx="0.00048" ixy="3.01E-06" ixz="1.11E-06" iyy="0.000884" iyz="1.42E-06" izz="0.000596" />
    </inertial>
    <visual>
      <origin rpy="3.1415 0 0" xyz="0 0 0" />
      <geometry>
        <mesh filename="/home/rml/ros2_ws/install/go2_description/share/go2_description/models/go2/dae/hip.dae" />
      </geometry>
      <material name="">
        <color rgba="1 1 1 1" />
      </material>
    </visual>
    <collision>
      <origin rpy="1.5707963267948966 0 0" xyz="0 -0.08 0" />
      <geometry>
        <cylinder length="0.04" radius="0.046" />
      </geometry>
    </collision>
  </link>
  <joint name="j_abad_2" type="revolute">
    <origin rpy="0 0 0" xyz="0.1934 -0.0465 0" />
    <parent link="body" />
    <child link="hip2" />
    <axis xyz="1 0 0" />
    <limit effort="23.7" lower="-1.0472" upper="1.0472" velocity="30.1" />
  </joint>
  <link name="hip2_rotor">
    <inertial>
      <origin rpy="0 0 0" xyz="0.0 0.0 0.0" />
      <mass value="0.089" />
      <inertia ixx="0.000111842" ixy="0.0" ixz="0.0" iyy="0.000059647" iyz="0.0" izz="0.000059647" />
    </inertial>
  </link>
  <joint name="hip2_rotor_joint" type="fixed">
    <origin rpy="0 0 0" xyz="0.11215 -0.04675 0" />
    <parent link="body" />
    <child link="hip2_rotor" />
  </joint>
  <link name="upper2">
    <inertial>
      <origin rpy="0 0 0" xyz="-0.00374 0.0223 -0.0327" />
      <mass value="1.152" />
      <inertia ixx="0.00584" ixy="-8.72E-05" ixz="-0.000289" iyy="0.0058" iyz="-0.000808" izz="0.00103" />
    </inertial>
    <visual>
      <origin rpy="0 0 0" xyz="0 0 0" />
      <geometry>
        <mesh filename="/home/rml/ros2_ws/install/go2_description/share/go2_description/models/go2/dae/thigh_mirror.dae" />
      </geometry>
      <material name="">
        <color rgba="1 1 1 1" />
      </material>
    </visual>
    <collision>
      <origin rpy="0 1.5707963267948966 0" xyz="0 0 -0.1065" />
      <geometry>
        <box size="0.213 0.0245 0.034" />
      </geometry>
    </collision>
  </link>
  <joint name="j_hip_2" type="revolute">
    <origin rpy="0 0 0" xyz="0 -0.0955 0" />
    <parent link="hip2" />
    <child link="upper2" />
    <axis xyz="0 1 0" />
    <limit effort="23.7" lower="-1.5708" upper="3.4907" velocity="30.1" />
  </joint>
  <link name="upper2_rotor">
    <inertial>
      <origin rpy="0 0 0" xyz="0.0 0.0 0.0" />
      <mass value="0.089" />
      <inertia ixx="0.000059647" ixy="0.0" ixz="0.0" iyy="0.000111842" iyz="0.0" izz="0.000059647" />
    </inertial>
  </link>
  <joint name="upper2_rotor_joint" type="fixed">
    <origin rpy="0 0 0" xyz="0 0.00015 0" />
    <parent link="hip2" />
    <child link="upper2_rotor" />
  </joint>
  <link name="lower2">
    <inertial>
      <origin rpy="0 0 0" xyz="0.00548 0.000975 -0.115" />
      <mass value="0.154" />
      <inertia ixx="0.00108" ixy="-3.4E-07" ixz="1.72E-05" iyy="0.0011" iyz="-8.28E-06" izz="3.29E-05" />
    </inertial>
    <visual>
      <origin rpy="0 0 0" xyz="0 0 0" />
      <geometry>
        <mesh filename="/home/rml/ros2_ws/install/go2_description/share/go2_description/models/go2/dae/calf_mirror.dae" />
      </geometry>
      <material name="">
        <color rgba="1 1 1 1" />
      </material>
    </visual>
    <collision>
      <origin rpy="0 -0.2 0" xyz="0.01 0 -0.06" />
      <geometry>
        <cylinder length="0.12" radius="0.013" />
      </geometry>
    </collision>
  </link>
  <joint name="j_knee_2" type="revolute">
    <origin rpy="0 0 0" xyz="0 0 -0.213" />
    <parent link="upper2" />
    <child link="lower2" />
    <axis xyz="0 1 0" />
    <limit effort="45.43" lower="-2.7227" upper="-0.83776" velocity="15.70" />
  </joint>
  <link name="lower2_lower">
    <collision>
      <origin rpy="0 0 0" xyz="0 0 0" />
      <geometry>
        <cylinder length="0.065" radius="0.011" />
      </geometry>
    </collision>
  <inertial><origin rpy="0 0 0" xyz="0 0 0" /><mass value="0.001" /><inertia ixx="1e-06" ixy="0" ixz="0" iyy="1e-06" iyz="0" izz="1e-06" /></inertial></link>
  <joint name="lower2_lower_joint" type="fixed">
    <origin rpy="0 0.05 0" xyz="0.020 0 -0.148" />
    <parent link="lower2" />
    <child link="lower2_lower" />
    <axis xyz="0 0 0" />
  </joint>
  <link name="lower2_lower1">
    <collision>
      <origin rpy="0 0 0" xyz="0 0 0" />
      <geometry>
        <cylinder length="0.03" radius="0.0155" />
      </geometry>
    </collision>
  <inertial><origin rpy="0 0 0" xyz="0 0 0" /><mass value="0.001" /><inertia ixx="1e-06" ixy="0" ixz="0" iyy="1e-06" iyz="0" izz="1e-06" /></inertial></link>
  <joint name="lower2_lower1_joint" type="fixed">
    <origin rpy="0 0.48 0" xyz="-0.01 0 -0.04" />
    <parent link="lower2_lower" />
    <child link="lower2_lower1" />
    <axis xyz="0 0 0" />
  </joint>
  <link name="lower2_rotor">
    <inertial>
      <origin rpy="0 0 0" xyz="0.0 0.0 0.0" />
      <mass value="0.089" />
      <inertia ixx="0.000059647" ixy="0.0" ixz="0.0" iyy="0.000111842" iyz="0.0" izz="0.000059647" />
    </inertial>
  </link>
  <joint name="lower2_rotor_joint" type="fixed">
    <origin rpy="0 0 0" xyz="0 0.03235 0" />
    <parent link="upper2" />
    <child link="lower2_rotor" />
  </joint>
  <link name="toe2">
    <inertial>
      <origin rpy="0 0 0" xyz="0 0 0" />
      <mass value="0.04" />
      <inertia ixx="9.6e-06" ixy="0" ixz="0" iyy="9.6e-06" iyz="0" izz="9.6e-06" />
    </inertial>
    <visual>
      <origin rpy="0 0 0" xyz="0 0 0" />
      <geometry>
        <mesh filename="/home/rml/ros2_ws/install/go2_description/share/go2_description/models/go2/dae/foot.dae" />
      </geometry>
      <material name="">
        <color rgba="1 1 1 1" />
      </material>
    </visual>
    <collision>
      <origin rpy="0 0 0" xyz="-0.002 0 0" />
      <geometry>
        <sphere radius="0.022" />
      </geometry>
    </collision>
  </link>
  <joint name="jtoe2" type="fixed">
    <origin rpy="0 0 0" xyz="0 0 -0.213" />
    <parent link="lower2" />
    <child link="toe2" />
    <axis xyz="0 0 0" />
  </joint>
  <link name="hip1">
    <inertial>
      <origin rpy="0 0 0" xyz="0.0054 0.00194 -0.000105" />
      <mass value="0.678" />
      <inertia ixx="0.00048" ixy="3.01E-06" ixz="-1.11E-06" iyy="0.000884" iyz="-1.42E-06" izz="0.000596" />
    </inertial>
    <visual>
      <origin rpy="0 3.1415 0" xyz="0 0 0" />
      <geometry>
        <mesh filename="/home/rml/ros2_ws/install/go2_description/share/go2_description/models/go2/dae/hip.dae" />
      </geometry>
      <material name="">
        <color rgba="1 1 1 1" />
      </material>
    </visual>
    <collision>
      <origin rpy="1.5707963267948966 0 0" xyz="0 0.08 0" />
      <geometry>
        <cylinder length="0.04" radius="0.046" />
      </geometry>
    </collision>
  </link>
  <joint name="j_abad_1" type="revolute">
    <origin rpy="0 0 0" xyz="-0.1934 0.0465 0" />
    <parent link="body" />
    <child link="hip1" />
    <axis xyz="1 0 0" />
    <limit effort="23.7" lower="-1.0472" upper="1.0472" velocity="30.1" />
  </joint>
  <link name="hip1_rotor">
    <inertial>
      <origin rpy="0 0 0" xyz="0.0 0.0 0.0" />
      <mass value="0.089" />
      <inertia ixx="0.000111842" ixy="0.0" ixz="0.0" iyy="0.000059647" iyz="0.0" izz="0.000059647" />
    </inertial>
  </link>
  <joint name="hip1_rotor_joint" type="fixed">
    <origin rpy="0 0 0" xyz="-0.11215 0.04675 0" />
    <parent link="body" />
    <child link="hip1_rotor" />
  </joint>
  <link name="upper1">
    <inertial>
      <origin rpy="0 0 0" xyz="-0.00374 -0.0223 -0.0327" />
      <mass value="1.152" />
      <inertia ixx="0.00584" ixy="8.72E-05" ixz="-0.000289" iyy="0.0058" iyz="0.000808" izz="0.00103" />
    </inertial>
    <visual>
      <origin rpy="0 0 0" xyz="0 0 0" />
      <geometry>
        <mesh filename="/home/rml/ros2_ws/install/go2_description/share/go2_description/models/go2/dae/thigh.dae" />
      </geometry>
      <material name="">
        <color rgba="1 1 1 1" />
      </material>
    </visual>
    <collision>
      <origin rpy="0 1.5707963267948966 0" xyz="0 0 -0.1065" />
      <geometry>
        <box size="0.213 0.0245 0.034" />
      </geometry>
    </collision>
  </link>
  <joint name="j_hip_1" type="revolute">
    <origin rpy="0 0 0" xyz="0 0.0955 0" />
    <parent link="hip1" />
    <child link="upper1" />
    <axis xyz="0 1 0" />
    <limit effort="23.7" lower="-0.5236" upper="4.5379" velocity="30.1" />
  </joint>
  <link name="upper1_rotor">
    <inertial>
      <origin rpy="0 0 0" xyz="0.0 0.0 0.0" />
      <mass value="0.089" />
      <inertia ixx="0.000059647" ixy="0.0" ixz="0.0" iyy="0.000111842" iyz="0.0" izz="0.000059647" />
    </inertial>
  </link>
  <joint name="upper1_rotor_joint" type="fixed">
    <origin rpy="0 0 0" xyz="0 -0.00015 0" />
    <parent link="hip1" />
    <child link="upper1_rotor" />
  </joint>
  <link name="lower1">
    <inertial>
      <origin rpy="0 0 0" xyz="0.00548 -0.000975 -0.115" />
      <mass value="0.154" />
      <inertia ixx="0.00108" ixy="3.4E-07" ixz="1.72E-05" iyy="0.0011" iyz="8.28E-06" izz="3.29E-05" />
    </inertial>
    <visual>
      <origin rpy="0 0 0" xyz="0 0 0" />
      <geometry>
        <mesh filename="/home/rml/ros2_ws/install/go2_description/share/go2_description/models/go2/dae/calf.dae" />
      </geometry>
      <material name="">
        <color rgba="1 1 1 1" />
      </material>
    </visual>
    <collision>
      <origin rpy="0 -0.2 0" xyz="0.01 0 -0.06" />
      <geometry>
        <cylinder length="0.12" radius="0.013" />
      </geometry>
    </collision>
  </link>
  <joint name="j_knee_1" type="revolute">
    <origin rpy="0 0 0" xyz="0 0 -0.213" />
    <parent link="upper1" />
    <child link="lower1" />
    <axis xyz="0 1 0" />
    <limit effort="45.43" lower="-2.7227" upper="-0.83776" velocity="15.70" />
  </joint>
  <link name="lower1_lower">
    <collision>
      <origin rpy="0 0 0" xyz="0 0 0" />
      <geometry>
        <cylinder length="0.065" radius="0.011" />
      </geometry>
    </collision>
  <inertial><origin rpy="0 0 0" xyz="0 0 0" /><mass value="0.001" /><inertia ixx="1e-06" ixy="0" ixz="0" iyy="1e-06" iyz="0" izz="1e-06" /></inertial></link>
  <joint name="lower1_lower_joint" type="fixed">
    <origin rpy="0 0.05 0" xyz="0.020 0 -0.148" />
    <parent link="lower1" />
    <child link="lower1_lower" />
    <axis xyz="0 0 0" />
  </joint>
  <link name="lower1_lower1">
    <collision>
      <origin rpy="0 0 0" xyz="0 0 0" />
      <geometry>
        <cylinder length="0.03" radius="0.0155" />
      </geometry>
    </collision>
  <inertial><origin rpy="0 0 0" xyz="0 0 0" /><mass value="0.001" /><inertia ixx="1e-06" ixy="0" ixz="0" iyy="1e-06" iyz="0" izz="1e-06" /></inertial></link>
  <joint name="lower1_lower1_joint" type="fixed">
    <origin rpy="0 0.48 0" xyz="-0.01 0 -0.04" />
    <parent link="lower1_lower" />
    <child link="lower1_lower1" />
    <axis xyz="0 0 0" />
  </joint>
  <link name="lower1_rotor">
    <inertial>
      <origin rpy="0 0 0" xyz="0.0 0.0 0.0" />
      <mass value="0.089" />
      <inertia ixx="0.000059647" ixy="0.0" ixz="0.0" iyy="0.000111842" iyz="0.0" izz="0.000059647" />
    </inertial>
  </link>
  <joint name="lower1_rotor_joint" type="fixed">
    <origin rpy="0 0 0" xyz="0 -0.03235 0" />
    <parent link="upper1" />
    <child link="lower1_rotor" />
  </joint>
  <link name="toe1">
    <inertial>
      <origin rpy="0 0 0" xyz="0 0 0" />
      <mass value="0.04" />
      <inertia ixx="9.6e-06" ixy="0" ixz="0" iyy="9.6e-06" iyz="0" izz="9.6e-06" />
    </inertial>
    <visual>
      <origin rpy="0 0 0" xyz="0 0 0" />
      <geometry>
        <mesh filename="/home/rml/ros2_ws/install/go2_description/share/go2_description/models/go2/dae/foot.dae" />
      </geometry>
      <material name="">
        <color rgba="1 1 1 1" />
      </material>
    </visual>
    <collision>
      <origin rpy="0 0 0" xyz="-0.002 0 0" />
      <geometry>
        <sphere radius="0.022" />
      </geometry>
    </collision>
  </link>
  <joint name="jtoe1" type="fixed">
    <origin rpy="0 0 0" xyz="0 0 -0.213" />
    <parent link="lower1" />
    <child link="toe1" />
    <axis xyz="0 0 0" />
  </joint>
  <link name="hip3">
    <inertial>
      <origin rpy="0 0 0" xyz="0.0054 -0.00194 -0.000105" />
      <mass value="0.678" />
      <inertia ixx="0.00048" ixy="-3.01E-06" ixz="-1.11E-06" iyy="0.000884" iyz="1.42E-06" izz="0.000596" />
    </inertial>
    <visual>
      <origin rpy="3.1415 3.1415 0" xyz="0 0 0" />
      <geometry>
        <mesh filename="/home/rml/ros2_ws/install/go2_description/share/go2_description/models/go2/dae/hip.dae" />
      </geometry>
      <material name="">
        <color rgba="1 1 1 1" />
      </material>
    </visual>
    <collision>
      <origin rpy="1.5707963267948966 0 0" xyz="0 -0.08 0" />
      <geometry>
        <cylinder length="0.04" radius="0.046" />
      </geometry>
    </collision>
  </link>
  <joint name="j_abad_3" type="revolute">
    <origin rpy="0 0 0" xyz="-0.1934 -0.0465 0" />
    <parent link="body" />
    <child link="hip3" />
    <axis xyz="1 0 0" />
    <limit effort="23.7" lower="-1.0472" upper="1.0472" velocity="30.1" />
  </joint>
  <link name="hip3_rotor">
    <inertial>
      <origin rpy="0 0 0" xyz="0.0 0.0 0.0" />
      <mass value="0.089" />
      <inertia ixx="0.000111842" ixy="0.0" ixz="0.0" iyy="0.000059647" iyz="0.0" izz="0.000059647" />
    </inertial>
  </link>
  <joint name="hip3_rotor_joint" type="fixed">
    <origin rpy="0 0 0" xyz="-0.11215 -0.04675 0" />
    <parent link="body" />
    <child link="hip3_rotor" />
  </joint>
  <link name="upper3">
    <inertial>
      <origin rpy="0 0 0" xyz="-0.00374 0.0223 -0.0327" />
      <mass value="1.152" />
      <inertia ixx="0.00584" ixy="-8.72E-05" ixz="-0.000289" iyy="0.0058" iyz="-0.000808" izz="0.00103" />
    </inertial>
    <visual>
      <origin rpy="0 0 0" xyz="0 0 0" />
      <geometry>
        <mesh filename="/home/rml/ros2_ws/install/go2_description/share/go2_description/models/go2/dae/thigh_mirror.dae" />
      </geometry>
      <material name="">
        <color rgba="1 1 1 1" />
      </material>
    </visual>
    <collision>
      <origin rpy="0 1.5707963267948966 0" xyz="0 0 -0.1065" />
      <geometry>
        <box size="0.213 0.0245 0.034" />
      </geometry>
    </collision>
  </link>
  <joint name="j_hip_3" type="revolute">
    <origin rpy="0 0 0" xyz="0 -0.0955 0" />
    <parent link="hip3" />
    <child link="upper3" />
    <axis xyz="0 1 0" />
    <limit effort="23.7" lower="-0.5236" upper="4.5379" velocity="30.1" />
  </joint>
  <link name="upper3_rotor">
    <inertial>
      <origin rpy="0 0 0" xyz="0.0 0.0 0.0" />
      <mass value="0.089" />
      <inertia ixx="0.000059647" ixy="0.0" ixz="0.0" iyy="0.000111842" iyz="0.0" izz="0.000059647" />
    </inertial>
  </link>
  <joint name="upper3_rotor_joint" type="fixed">
    <origin rpy="0 0 0" xyz="0 0.00015 0" />
    <parent link="hip3" />
    <child link="upper3_rotor" />
  </joint>
  <link name="lower3">
    <inertial>
      <origin rpy="0 0 0" xyz="0.00548 0.000975 -0.115" />
      <mass value="0.154" />
      <inertia ixx="0.00108" ixy="-3.4E-07" ixz="1.72E-05" iyy="0.0011" iyz="-8.28E-06" izz="3.29E-05" />
    </inertial>
    <visual>
      <origin rpy="0 0 0" xyz="0 0 0" />
      <geometry>
        <mesh filename="/home/rml/ros2_ws/install/go2_description/share/go2_description/models/go2/dae/calf_mirror.dae" />
      </geometry>
      <material name="">
        <color rgba="1 1 1 1" />
      </material>
    </visual>
    <collision>
      <origin rpy="0 -0.2 0" xyz="0.01 0 -0.06" />
      <geometry>
        <cylinder length="0.12" radius="0.013" />
      </geometry>
    </collision>
  </link>
  <joint name="j_knee_3" type="revolute">
    <origin rpy="0 0 0" xyz="0 0 -0.213" />
    <parent link="upper3" />
    <child link="lower3" />
    <axis xyz="0 1 0" />
    <limit effort="45.43" lower="-2.7227" upper="-0.83776" velocity="15.70" />
  </joint>
  <link name="lower3_lower">
    <collision>
      <origin rpy="0 0 0" xyz="0 0 0" />
      <geometry>
        <cylinder length="0.065" radius="0.011" />
      </geometry>
    </collision>
  <inertial><origin rpy="0 0 0" xyz="0 0 0" /><mass value="0.001" /><inertia ixx="1e-06" ixy="0" ixz="0" iyy="1e-06" iyz="0" izz="1e-06" /></inertial></link>
  <joint name="lower3_lower_joint" type="fixed">
    <origin rpy="0 0.05 0" xyz="0.020 0 -0.148" />
    <parent link="lower3" />
    <child link="lower3_lower" />
    <axis xyz="0 0 0" />
  </joint>
  <link name="lower3_lower1">
    <collision>
      <origin rpy="0 0 0" xyz="0 0 0" />
      <geometry>
        <cylinder length="0.03" radius="0.0155" />
      </geometry>
    </collision>
  <inertial><origin rpy="0 0 0" xyz="0 0 0" /><mass value="0.001" /><inertia ixx="1e-06" ixy="0" ixz="0" iyy="1e-06" iyz="0" izz="1e-06" /></inertial></link>
  <joint name="lower3_lower1_joint" type="fixed">
    <origin rpy="0 0.48 0" xyz="-0.01 0 -0.04" />
    <parent link="lower3_lower" />
    <child link="lower3_lower1" />
    <axis xyz="0 0 0" />
  </joint>
  <link name="lower3_rotor">
    <inertial>
      <origin rpy="0 0 0" xyz="0.0 0.0 0.0" />
      <mass value="0.089" />
      <inertia ixx="0.000059647" ixy="0.0" ixz="0.0" iyy="0.000111842" iyz="0.0" izz="0.000059647" />
    </inertial>
  </link>
  <joint name="lower3_rotor_joint" type="fixed">
    <origin rpy="0 0 0" xyz="0 0.03235 0" />
    <parent link="upper3" />
    <child link="lower3_rotor" />
  </joint>
  <link name="toe3">
    <inertial>
      <origin rpy="0 0 0" xyz="0 0 0" />
      <mass value="0.04" />
      <inertia ixx="9.6e-06" ixy="0" ixz="0" iyy="9.6e-06" iyz="0" izz="9.6e-06" />
    </inertial>
    <visual>
      <origin rpy="0 0 0" xyz="0 0 0" />
      <geometry>
        <mesh filename="/home/rml/ros2_ws/install/go2_description/share/go2_description/models/go2/dae/foot.dae" />
      </geometry>
      <material name="">
        <color rgba="1 1 1 1" />
      </material>
    </visual>
    <collision>
      <origin rpy="0 0 0" xyz="-0.002 0 0" />
      <geometry>
        <sphere radius="0.022" />
      </geometry>
    </collision>
  </link>
  <joint name="jtoe3" type="fixed">
    <origin rpy="0 0 0" xyz="0 0 -0.213" />
    <parent link="lower3" />
    <child link="toe3" />
    <axis xyz="0 0 0" />
  </joint>
  <link name="imu">
    <inertial>
      <origin rpy="0 0 0" xyz="0 0 0" />
      <mass value="0.001" />
      <inertia ixx="1e-06" ixy="0" ixz="0" iyy="1e-06" iyz="0" izz="1e-06" />
    </inertial>
  </link>
  <joint name="imu_joint" type="fixed">
    <origin rpy="0 0 0" xyz="-0.02557 0 0.04232" />
    <parent link="body" />
    <child link="imu" />
    <axis xyz="0 0 0" />
  </joint>
  <link name="radar">
    <inertial>
      <origin rpy="0 0 0" xyz="0 0 0" />
      <mass value="0.001" />
      <inertia ixx="1e-06" ixy="0" ixz="0" iyy="1e-06" iyz="0" izz="1e-06" />
    </inertial>
  </link>
  <joint name="radar_joint" type="fixed">
    <origin rpy="0 2.8782 0" xyz="0.28945 0 -0.046825" />
    <parent link="body" />
    <child link="radar" />
    <axis xyz="0 0 0" />
  </joint>
  <joint name="front_camera_joint" type="fixed">
    <origin rpy="0 0 0" xyz="0.32715 -0.00003 0.04297" />
    <parent link="body" />
    <child link="front_camera" />
  </joint>
  <link name="front_camera">
  <inertial><origin rpy="0 0 0" xyz="0 0 0" /><mass value="0.001" /><inertia ixx="1e-06" ixy="0" ixz="0" iyy="1e-06" iyz="0" izz="1e-06" /></inertial></link>
</robot>